Workbook

Sheet 流水记账
A1: 日期 | B1: 星期 | C1: 分类 | D1: 事项 | E1: 详情 | F1: 支出金额 | G1: 收入金额 | H1: 当笔净额 | I1: 支付方式 | J1: 备注
A2: 2026年1月｜第一周（1月1日 - 1月7日）
A3: 日期 | B3: 星期 | C3: 分类 | D3: 事项 | E3: 详情 | F3: 支出金额 | G3: 收入金额 | H3: 当笔净额 | I3: 支付方式 | J3: 备注
A4: 46023 | B4: 星期四 | C4: 餐饮 | D4: 早餐 | H4: =IF(AND(F4="",G4=""),"",G4-F4)
A5: 46023 | B5: 星期四 | C5: 餐饮 | D5: 中餐 | H5: =IF(AND(F5="",G5=""),"",G5-F5)
A6: 46023 | B6: 星期四 | C6: 餐饮 | D6: 晚餐 | H6: =IF(AND(F6="",G6=""),"",G6-F6)
A7: 46023 | B7: 星期四 | C7: 奶茶/咖啡 | D7: 奶茶/咖啡 | H7: =IF(AND(F7="",G7=""),"",G7-F7)
A8: 46023 | B8: 星期四 | C8: 其他 | D8: 其他 | H8: =IF(AND(F8="",G8=""),"",G8-F8)
A9: 46023 | B9: 星期四 | C9: 其他 | D9: 其他 | H9: =IF(AND(F9="",G9=""),"",G9-F9)
A10: 46024 | B10: 星期五 | C10: 餐饮 | D10: 早餐 | H10: =IF(AND(F10="",G10=""),"",G10-F10)
A11: 46024 | B11: 星期五 | C11: 餐饮 | D11: 中餐 | H11: =IF(AND(F11="",G11=""),"",G11-F11)
A12: 46024 | B12: 星期五 | C12: 餐饮 | D12: 晚餐 | H12: =IF(AND(F12="",G12=""),"",G12-F12)
A13: 46024 | B13: 星期五 | C13: 奶茶/咖啡 | D13: 奶茶/咖啡 | H13: =IF(AND(F13="",G13=""),"",G13-F13)
A14: 46024 | B14: 星期五 | C14: 其他 | D14: 其他 | H14: =IF(AND(F14="",G14=""),"",G14-F14)
A15: 46024 | B15: 星期五 | C15: 其他 | D15: 其他 | H15: =IF(AND(F15="",G15=""),"",G15-F15)
... A45: 46029 | B45: 星期三 | C45: 其他 | D45: 其他 | H45: =IF(AND(F45="",G45=""),"",G45-F45)
A46: 本周小计 | F46: =SUMIFS($F:$F,$A:$A,">="&DATE(2026,1,1),$A:$A,"<="&DATE(2026,1,7)) | G46: =SUMIFS($G:$G,$A:$A,">="&DATE(2026,1,1),$A:$A,"<="&DATE(2026,1,7)) | H46: =G46-F46
A49: 2026年1月｜第二周（1月8日 - 1月14日）
A50: 日期 | B50: 星期 | C50: 分类 | D50: 事项 | E50: 详情 | F50: 支出金额 | G50: 收入金额 | H50: 当笔净额 | I50: 支付方式 | J50: 备注
A51: 46030 | B51: 星期四 | C51: 餐饮 | D51: 早餐 | H51: =IF(AND(F51="",G51=""),"",G51-F51)
A52: 46030 | B52: 星期四 | C52: 餐饮 | D52: 中餐 | H52: =IF(AND(F52="",G52=""),"",G52-F52)
A53: 46030 | B53: 星期四 | C53: 餐饮 | D53: 晚餐 | H53: =IF(AND(F53="",G53=""),"",G53-F53)
A54: 46030 | B54: 星期四 | C54: 奶茶/咖啡 | D54: 奶茶/咖啡 | H54: =IF(AND(F54="",G54=""),"",G54-F54)
A55: 46030 | B55: 星期四 | C55: 其他 | D55: 其他 | H55: =IF(AND(F55="",G55=""),"",G55-F55)
A56: 46030 | B56: 星期四 | C56: 其他 | D56: 其他 | H56: =IF(AND(F56="",G56=""),"",G56-F56)
A57: 46031 | B57: 星期五 | C57: 餐饮 | D57: 早餐 | H57: =IF(AND(F57="",G57=""),"",G57-F57)
A58: 46031 | B58: 星期五 | C58: 餐饮 | D58: 中餐 | H58: =IF(AND(F58="",G58=""),"",G58-F58)
A59: 46031 | B59: 星期五 | C59: 餐饮 | D59: 晚餐 | H59: =IF(AND(F59="",G59=""),"",G59-F59)
A60: 46031 | B60: 星期五 | C60: 奶茶/咖啡 | D60: 奶茶/咖啡 | H60: =IF(AND(F60="",G60=""),"",G60-F60)
A61: 46031 | B61: 星期五 | C61: 其他 | D61: 其他 | H61: =IF(AND(F61="",G61=""),"",G61-F61)
A62: 46031 | B62: 星期五 | C62: 其他 | D62: 其他 | H62: =IF(AND(F62="",G62=""),"",G62-F62)
... A92: 46036 | B92: 星期三 | C92: 其他 | D92: 其他 | H92: =IF(AND(F92="",G92=""),"",G92-F92)
A93: 本周小计 | F93: =SUMIFS($F:$F,$A:$A,">="&DATE(2026,1,8),$A:$A,"<="&DATE(2026,1,14)) | G93: =SUMIFS($G:$G,$A:$A,">="&DATE(2026,1,8),$A:$A,"<="&DATE(2026,1,14)) | H93: =G93-F93
A96: 2026年1月｜第三周（1月15日 - 1月21日）
A97: 日期 | B97: 星期 | C97: 分类 | D97: 事项 | E97: 详情 | F97: 支出金额 | G97: 收入金额 | H97: 当笔净额 | I97: 支付方式 | J97: 备注
A98: 46037 | B98: 星期四 | C98: 餐饮 | D98: 早餐 | H98: =IF(AND(F98="",G98=""),"",G98-F98)
A99: 46037 | B99: 星期四 | C99: 餐饮 | D99: 中餐 | H99: =IF(AND(F99="",G99=""),"",G99-F99)
A100: 46037 | B100: 星期四 | C100: 餐饮 | D100: 晚餐 | H100: =IF(AND(F100="",G100=""),"",G100-F100)
A101: 46037 | B101: 星期四 | C101: 奶茶/咖啡 | D101: 奶茶/咖啡 | H101: =IF(AND(F101="",G101=""),"",G101-F101)
A102: 46037 | B102: 星期四 | C102: 其他 | D102: 其他 | H102: =IF(AND(F102="",G102=""),"",G102-F102)
...

Sheet 按周汇总
A1: 按周汇总
A2: 周次 | B2: 起始日期 | C2: 结束日期 | D2: 支出合计 | E2: 收入合计 | F2: 本周净额 | G2: 累计余额 | H2: 备注
A3: 第1周 | B3: 46023 | C3: 46029 | D3: =SUMIFS('流水记账'!$F:$F,'流水记账'!$A:$A,">="&DATE(2026,1,1),'流水记账'!$A:$A,"<="&DATE(2026,1,7)) | E3: =SUMIFS('流水记账'!$G:$G,'流水记账'!$A:$A,">="&DATE(2026,1,1),'流水记账'!$A:$A,"<="&DATE(2026,1,7)) | F3: =E3-D3 | G3: ='按月汇总'!$B$2+SUM($F$3:F3)
A4: 第2周 | B4: 46030 | C4: 46036 | D4: =SUMIFS('流水记账'!$F:$F,'流水记账'!$A:$A,">="&DATE(2026,1,8),'流水记账'!$A:$A,"<="&DATE(2026,1,14)) | E4: =SUMIFS('流水记账'!$G:$G,'流水记账'!$A:$A,">="&DATE(2026,1,8),'流水记账'!$A:$A,"<="&DATE(2026,1,14)) | F4: =E4-D4 | G4: ='按月汇总'!$B$2+SUM($F$3:F4)
A5: 第3周 | B5: 46037 | C5: 46043 | D5: =SUMIFS('流水记账'!$F:$F,'流水记账'!$A:$A,">="&DATE(2026,1,15),'流水记账'!$A:$A,"<="&DATE(2026,1,21)) | E5: =SUMIFS('流水记账'!$G:$G,'流水记账'!$A:$A,">="&DATE(2026,1,15),'流水记账'!$A:$A,"<="&DATE(2026,1,21)) | F5: =E5-D5 | G5: ='按月汇总'!$B$2+SUM($F$3:F5)
A6: 第4周 | B6: 46044 | C6: 46050 | D6: =SUMIFS('流水记账'!$F:$F,'流水记账'!$A:$A,">="&DATE(2026,1,22),'流水记账'!$A:$A,"<="&DATE(2026,1,28)) | E6: =SUMIFS('流水记账'!$G:$G,'流水记账'!$A:$A,">="&DATE(2026,1,22),'流水记账'!$A:$A,"<="&DATE(2026,1,28)) | F6: =E6-D6 | G6: ='按月汇总'!$B$2+SUM($F$3:F6)
A7: 第5周 | B7: 46051 | C7: 46057 | D7: =SUMIFS('流水记账'!$F:$F,'流水记账'!$A:$A,">="&DATE(2026,1,29),'流水记账'!$A:$A,"<="&DATE(2026,2,4)) | E7: =SUMIFS('流水记账'!$G:$G,'流水记账'!$A:$A,">="&DATE(2026,1,29),'流水记账'!$A:$A,"<="&DATE(2026,2,4)) | F7: =E7-D7 | G7: ='按月汇总'!$B$2+SUM($F$3:F7)
A8: 第6周 | B8: 46058 | C8: 46064 | D8: =SUMIFS('流水记账'!$F:$F,'流水记账'!$A:$A,">="&DATE(2026,2,5),'流水记账'!$A:$A,"<="&DATE(2026,2,11)) | E8: =SUMIFS('流水记账'!$G:$G,'流水记账'!$A:$A,">="&DATE(2026,2,5),'流水记账'!$A:$A,"<="&DATE(2026,2,11)) | F8: =E8-D8 | G8: ='按月汇总'!$B$2+SUM($F$3:F8)
A9: 第7周 | B9: 46065 | C9: 46071 | D9: =SUMIFS('流水记账'!$F:$F,'流水记账'!$A:$A,">="&DATE(2026,2,12),'流水记账'!$A:$A,"<="&DATE(2026,2,18)) | E9: =SUMIFS('流水记账'!$G:$G,'流水记账'!$A:$A,">="&DATE(2026,2,12),'流水记账'!$A:$A,"<="&DATE(2026,2,18)) | F9: =E9-D9 | G9: ='按月汇总'!$B$2+SUM($F$3:F9)
A10: 第8周 | B10: 46072 | C10: 46078 | D10: =SUMIFS('流水记账'!$F:$F,'流水记账'!$A:$A,">="&DATE(2026,2,19),'流水记账'!$A:$A,"<="&DATE(2026,2,25)) | E10: =SUMIFS('流水记账'!$G:$G,'流水记账'!$A:$A,">="&DATE(2026,2,19),'流水记账'!$A:$A,"<="&DATE(2026,2,25)) | F10: =E10-D10 | G10: ='按月汇总'!$B$2+SUM($F$3:F10)
A11: 第9周 | B11: 46079 | C11: 46085 | D11: =SUMIFS('流水记账'!$F:$F,'流水记账'!$A:$A,">="&DATE(2026,2,26),'流水记账'!$A:$A,"<="&DATE(2026,3,4)) | E11: =SUMIFS('流水记账'!$G:$G,'流水记账'!$A:$A,">="&DATE(2026,2,26),'流水记账'!$A:$A,"<="&DATE(2026,3,4)) | F11: =E11-D11 | G11: ='按月汇总'!$B$2+SUM($F$3:F11)
A12: 第10周 | B12: 46086 | C12: 46092 | D12: =SUMIFS('流水记账'!$F:$F,'流水记账'!$A:$A,">="&DATE(2026,3,5),'流水记账'!$A:$A,"<="&DATE(2026,3,11)) | E12: =SUMIFS('流水记账'!$G:$G,'流水记账'!$A:$A,">="&DATE(2026,3,5),'流水记账'!$A:$A,"<="&DATE(2026,3,11)) | F12: =E12-D12 | G12: ='按月汇总'!$B$2+SUM($F$3:F12)
A13: 第11周 | B13: 46093 | C13: 46099 | D13: =SUMIFS('流水记账'!$F:$F,'流水记账'!$A:$A,">="&DATE(2026,3,12),'流水记账'!$A:$A,"<="&DATE(2026,3,18)) | E13: =SUMIFS('流水记账'!$G:$G,'流水记账'!$A:$A,">="&DATE(2026,3,12),'流水记账'!$A:$A,"<="&DATE(2026,3,18)) | F13: =E13-D13 | G13: ='按月汇总'!$B$2+SUM($F$3:F13)
A14: 第12周 | B14: 46100 | C14: 46106 | D14: =SUMIFS('流水记账'!$F:$F,'流水记账'!$A:$A,">="&DATE(2026,3,19),'流水记账'!$A:$A,"<="&DATE(2026,3,25)) | E14: =SUMIFS('流水记账'!$G:$G,'流水记账'!$A:$A,">="&DATE(2026,3,19),'流水记账'!$A:$A,"<="&DATE(2026,3,25)) | F14: =E14-D14 | G14: ='按月汇总'!$B$2+SUM($F$3:F14)
A15: 第13周 | B15: 46107 | C15: 46113 | D15: =SUMIFS('流水记账'!$F:$F,'流水记账'!$A:$A,">="&DATE(2026,3,26),'流水记账'!$A:$A,"<="&DATE(2026,4,1)) | E15: =SUMIFS('流水记账'!$G:$G,'流水记账'!$A:$A,">="&DATE(2026,3,26),'流水记账'!$A:$A,"<="&DATE(2026,4,1)) | F15: =E15-D15 | G15: ='按月汇总'!$B$2+SUM($F$3:F15)
A16: 第14周 | B16: 46114 | C16: 46120 | D16: =SUMIFS('流水记账'!$F:$F,'流水记账'!$A:$A,">="&DATE(2026,4,2),'流水记账'!$A:$A,"<="&DATE(2026,4,8)) | E16: =SUMIFS('流水记账'!$G:$G,'流水记账'!$A:$A,">="&DATE(2026,4,2),'流水记账'!$A:$A,"<="&DATE(2026,4,8)) | F16: =E16-D16 | G16: ='按月汇总'!$B$2+SUM($F$3:F16)
A17: 第15周 | B17: 46121 | C17: 46127 | D17: =SUMIFS('流水记账'!$F:$F,'流水记账'!$A:$A,">="&DATE(2026,4,9),'流水记账'!$A:$A,"<="&DATE(2026,4,15)) | E17: =SUMIFS('流水记账'!$G:$G,'流水记账'!$A:$A,">="&DATE(2026,4,9),'流水记账'!$A:$A,"<="&DATE(2026,4,15)) | F17: =E17-D17 | G17: ='按月汇总'!$B$2+SUM($F$3:F17)
A18: 第16周 | B18: 46128 | C18: 46134 | D18: =SUMIFS('流水记账'!$F:$F,'流水记账'!$A:$A,">="&DATE(2026,4,16),'流水记账'!$A:$A,"<="&DATE(2026,4,22)) | E18: =SUMIFS('流水记账'!$G:$G,'流水记账'!$A:$A,">="&DATE(2026,4,16),'流水记账'!$A:$A,"<="&DATE(2026,4,22)) | F18: =E18-D18 | G18: ='按月汇总'!$B$2+SUM($F$3:F18)
A19: 第17周 | B19: 46135 | C19: 46141 | D19: =SUMIFS('流水记账'!$F:$F,'流水记账'!$A:$A,">="&DATE(2026,4,23),'流水记账'!$A:$A,"<="&DATE(2026,4,29)) | E19: =SUMIFS('流水记账'!$G:$G,'流水记账'!$A:$A,">="&DATE(2026,4,23),'流水记账'!$A:$A,"<="&DATE(2026,4,29)) | F19: =E19-D19 | G19: ='按月汇总'!$B$2+SUM($F$3:F19)
A20: 第18周 | B20: 46142 | C20: 46148 | D20: =SUMIFS('流水记账'!$F:$F,'流水记账'!$A:$A,">="&DATE(2026,4,30),'流水记账'!$A:$A,"<="&DATE(2026,5,6)) | E20: =SUMIFS('流水记账'!$G:$G,'流水记账'!$A:$A,">="&DATE(2026,4,30),'流水记账'!$A:$A,"<="&DATE(2026,5,6)) | F20: =E20-D20 | G20: ='按月汇总'!$B$2+SUM($F$3:F20)
A21: 第19周 | B21: 46149 | C21: 46155 | D21: =SUMIFS('流水记账'!$F:$F,'流水记账'!$A:$A,">="&DATE(2026,5,7),'流水记账'!$A:$A,"<="&DATE(2026,5,13)) | E21: =SUMIFS('流水记账'!$G:$G,'流水记账'!$A:$A,">="&DATE(2026,5,7),'流水记账'!$A:$A,"<="&DATE(2026,5,13)) | F21: =E21-D21 | G21: ='按月汇总'!$B$2+SUM($F$3:F21)
A22: 第20周 | B22: 46156 | C22: 46162 | D22: =SUMIFS('流水记账'!$F:$F,'流水记账'!$A:$A,">="&DATE(2026,5,14),'流水记账'!$A:$A,"<="&DATE(2026,5,20)) | E22: =SUMIFS('流水记账'!$G:$G,'流水记账'!$A:$A,">="&DATE(2026,5,14),'流水记账'!$A:$A,"<="&DATE(2026,5,20)) | F22: =E22-D22 | G22: ='按月汇总'!$B$2+SUM($F$3:F22)
A23: 第21周 | B23: 46163 | C23: 46169 | D23: =SUMIFS('流水记账'!$F:$F,'流水记账'!$A:$A,">="&DATE(2026,5,21),'流水记账'!$A:$A,"<="&DATE(2026,5,27)) | E23: =SUMIFS('流水记账'!$G:$G,'流水记账'!$A:$A,">="&DATE(2026,5,21),'流水记账'!$A:$A,"<="&DATE(2026,5,27)) | F23: =E23-D23 | G23: ='按月汇总'!$B$2+SUM($F$3:F23)
A24: 第22周 | B24: 46170 | C24: 46176 | D24: =SUMIFS('流水记账'!$F:$F,'流水记账'!$A:$A,">="&DATE(2026,5,28),'流水记账'!$A:$A,"<="&DATE(2026,6,3)) | E24: =SUMIFS('流水记账'!$G:$G,'流水记账'!$A:$A,">="&DATE(2026,5,28),'流水记账'!$A:$A,"<="&DATE(2026,6,3)) | F24: =E24-D24 | G24: ='按月汇总'!$B$2+SUM($F$3:F24)
A25: 第23周 | B25: 46177 | C25: 46183 | D25: =SUMIFS('流水记账'!$F:$F,'流水记账'!$A:$A,">="&DATE(2026,6,4),'流水记账'!$A:$A,"<="&DATE(2026,6,10)) | E25: =SUMIFS('流水记账'!$G:$G,'流水记账'!$A:$A,">="&DATE(2026,6,4),'流水记账'!$A:$A,"<="&DATE(2026,6,10)) | F25: =E25-D25 | G25: ='按月汇总'!$B$2+SUM($F$3:F25)
A26: 第24周 | B26: 46184 | C26: 46190 | D26: =SUMIFS('流水记账'!$F:$F,'流水记账'!$A:$A,">="&DATE(2026,6,11),'流水记账'!$A:$A,"<="&DATE(2026,6,17)) | E26: =SUMIFS('流水记账'!$G:$G,'流水记账'!$A:$A,">="&DATE(2026,6,11),'流水记账'!$A:$A,"<="&DATE(2026,6,17)) | F26: =E26-D26 | G26: ='按月汇总'!$B$2+SUM($F$3:F26)
A27: 第25周 | B27: 46191 | C27: 46197 | D27: =SUMIFS('流水记账'!$F:$F,'流水记账'!$A:$A,">="&DATE(2026,6,18),'流水记账'!$A:$A,"<="&DATE(2026,6,24)) | E27: =SUMIFS('流水记账'!$G:$G,'流水记账'!$A:$A,">="&DATE(2026,6,18),'流水记账'!$A:$A,"<="&DATE(2026,6,24)) | F27: =E27-D27 | G27: ='按月汇总'!$B$2+SUM($F$3:F27)
A28: 第26周 | B28: 46198 | C28: 46204 | D28: =SUMIFS('流水记账'!$F:$F,'流水记账'!$A:$A,">="&DATE(2026,6,25),'流水记账'!$A:$A,"<="&DATE(2026,7,1)) | E28: =SUMIFS('流水记账'!$G:$G,'流水记账'!$A:$A,">="&DATE(2026,6,25),'流水记账'!$A:$A,"<="&DATE(2026,7,1)) | F28: =E28-D28 | G28: ='按月汇总'!$B$2+SUM($F$3:F28)
A29: 第27周 | B29: 46205 | C29: 46211 | D29: =SUMIFS('流水记账'!$F:$F,'流水记账'!$A:$A,">="&DATE(2026,7,2),'流水记账'!$A:$A,"<="&DATE(2026,7,8)) | E29: =SUMIFS('流水记账'!$G:$G,'流水记账'!$A:$A,">="&DATE(2026,7,2),'流水记账'!$A:$A,"<="&DATE(2026,7,8)) | F29: =E29-D29 | G29: ='按月汇总'!$B$2+SUM($F$3:F29)
A30: 第28周 | B30: 46212 | C30: 46218 | D30: =SUMIFS('流水记账'!$F:$F,'流水记账'!$A:$A,">="&DATE(2026,7,9),'流水记账'!$A:$A,"<="&DATE(2026,7,15)) | E30: =SUMIFS('流水记账'!$G:$G,'流水记账'!$A:$A,">="&DATE(2026,7,9),'流水记账'!$A:$A,"<="&DATE(2026,7,15)) | F30: =E30-D30 | G30: ='按月汇总'!$B$2+SUM($F$3:F30)
A31: 第29周 | B31: 46219 | C31: 46225 | D31: =SUMIFS('流水记账'!$F:$F,'流水记账'!$A:$A,">="&DATE(2026,7,16),'流水记账'!$A:$A,"<="&DATE(2026,7,22)) | E31: =SUMIFS('流水记账'!$G:$G,'流水记账'!$A:$A,">="&DATE(2026,7,16),'流水记账'!$A:$A,"<="&DATE(2026,7,22)) | F31: =E31-D31 | G31: ='按月汇总'!$B$2+SUM($F$3:F31)
A32: 第30周 | B32: 46226 | C32: 46232 | D32: =SUMIFS('流水记账'!$F:$F,'流水记账'!$A:$A,">="&DATE(2026,7,23),'流水记账'!$A:$A,"<="&DATE(2026,7,29)) | E32: =SUMIFS('流水记账'!$G:$G,'流水记账'!$A:$A,">="&DATE(2026,7,23),'流水记账'!$A:$A,"<="&DATE(2026,7,29)) | F32: =E32-D32 | G32: ='按月汇总'!$B$2+SUM($F$3:F32)
A33: 第31周 | B33: 46233 | C33: 46239 | D33: =SUMIFS('流水记账'!$F:$F,'流水记账'!$A:$A,">="&DATE(2026,7,30),'流水记账'!$A:$A,"<="&DATE(2026,8,5)) | E33: =SUMIFS('流水记账'!$G:$G,'流水记账'!$A:$A,">="&DATE(2026,7,30),'流水记账'!$A:$A,"<="&DATE(2026,8,5)) | F33: =E33-D33 | G33: ='按月汇总'!$B$2+SUM($F$3:F33)
A34: 第32周 | B34: 46240 | C34: 46246 | D34: =SUMIFS('流水记账'!$F:$F,'流水记账'!$A:$A,">="&DATE(2026,8,6),'流水记账'!$A:$A,"<="&DATE(2026,8,12)) | E34: =SUMIFS('流水记账'!$G:$G,'流水记账'!$A:$A,">="&DATE(2026,8,6),'流水记账'!$A:$A,"<="&DATE(2026,8,12)) | F34: =E34-D34 | G34: ='按月汇总'!$B$2+SUM($F$3:F34)
A35: 第33周 | B35: 46247 | C35: 46253 | D35: =SUMIFS('流水记账'!$F:$F,'流水记账'!$A:$A,">="&DATE(2026,8,13),'流水记账'!$A:$A,"<="&DATE(2026,8,19)) | E35: =SUMIFS('流水记账'!$G:$G,'流水记账'!$A:$A,">="&DATE(2026,8,13),'流水记账'!$A:$A,"<="&DATE(2026,8,19)) | F35: =E35-D35 | G35: ='按月汇总'!$B$2+SUM($F$3:F35)
A36: 第34周 | B36: 46254 | C36: 46260 | D36: =SUMIFS('流水记账'!$F:$F,'流水记账'!$A:$A,">="&DATE(2026,8,20),'流水记账'!$A:$A,"<="&DATE(2026,8,26)) | E36: =SUMIFS('流水记账'!$G:$G,'流水记账'!$A:$A,">="&DATE(2026,8,20),'流水记账'!$A:$A,"<="&DATE(2026,8,26)) | F36: =E36-D36 | G36: ='按月汇总'!$B$2+SUM($F$3:F36)
A37: 第35周 | B37: 46261 | C37: 46267 | D37: =SUMIFS('流水记账'!$F:$F,'流水记账'!$A:$A,">="&DATE(2026,8,27),'流水记账'!$A:$A,"<="&DATE(2026,9,2)) | E37: =SUMIFS('流水记账'!$G:$G,'流水记账'!$A:$A,">="&DATE(2026,8,27),'流水记账'!$A:$A,"<="&DATE(2026,9,2)) | F37: =E37-D37 | G37: ='按月汇总'!$B$2+SUM($F$3:F37)
A38: 第36周 | B38: 46268 | C38: 46274 | D38: =SUMIFS('流水记账'!$F:$F,'流水记账'!$A:$A,">="&DATE(2026,9,3),'流水记账'!$A:$A,"<="&DATE(2026,9,9)) | E38: =SUMIFS('流水记账'!$G:$G,'流水记账'!$A:$A,">="&DATE(2026,9,3),'流水记账'!$A:$A,"<="&DATE(2026,9,9)) | F38: =E38-D38 | G38: ='按月汇总'!$B$2+SUM($F$3:F38)
A39: 第37周 | B39: 46275 | C39: 46281 | D39: =SUMIFS('流水记账'!$F:$F,'流水记账'!$A:$A,">="&DATE(2026,9,10),'流水记账'!$A:$A,"<="&DATE(2026,9,16)) | E39: =SUMIFS('流水记账'!$G:$G,'流水记账'!$A:$A,">="&DATE(2026,9,10),'流水记账'!$A:$A,"<="&DATE(2026,9,16)) | F39: =E39-D39 | G39: ='按月汇总'!$B$2+SUM($F$3:F39)
A40: 第38周 | B40: 46282 | C40: 46288 | D40: =SUMIFS('流水记账'!$F:$F,'流水记账'!$A:$A,">="&DATE(2026,9,17),'流水记账'!$A:$A,"<="&DATE(2026,9,23)) | E40: =SUMIFS('流水记账'!$G:$G,'流水记账'!$A:$A,">="&DATE(2026,9,17),'流水记账'!$A:$A,"<="&DATE(2026,9,23)) | F40: =E40-D40 | G40: ='按月汇总'!$B$2+SUM($F$3:F40)
...

Sheet 按月汇总
A1: 按月汇总
A2: 起始余额 | B2: 0 | C2: 总支出 | D2: =SUM(B6:B22) | E2: 总收入 | F2: =SUM(C6:C22)
A3: 总净额 | B3: =SUM(D6:D22) | C3: 当前余额 | D3: =B2+B3
A5: 月份 | B5: 支出合计 | C5: 收入合计 | D5: 本月净额 | E5: 累计余额 | F5: 备注
A6: 2026年1月 | B6: =SUMIFS('流水记账'!$F:$F,'流水记账'!$A:$A,">="&DATE(2026,1,1),'流水记账'!$A:$A,"<"&DATE(2026,2,1)) | C6: =SUMIFS('流水记账'!$G:$G,'流水记账'!$A:$A,">="&DATE(2026,1,1),'流水记账'!$A:$A,"<"&DATE(2026,2,1)) | D6: =C6-B6 | E6: =$B$2+SUM($D$6:D6)
A7: 2026年2月 | B7: =SUMIFS('流水记账'!$F:$F,'流水记账'!$A:$A,">="&DATE(2026,2,1),'流水记账'!$A:$A,"<"&DATE(2026,3,1)) | C7: =SUMIFS('流水记账'!$G:$G,'流水记账'!$A:$A,">="&DATE(2026,2,1),'流水记账'!$A:$A,"<"&DATE(2026,3,1)) | D7: =C7-B7 | E7: =$B$2+SUM($D$6:D7)
A8: 2026年3月 | B8: =SUMIFS('流水记账'!$F:$F,'流水记账'!$A:$A,">="&DATE(2026,3,1),'流水记账'!$A:$A,"<"&DATE(2026,4,1)) | C8: =SUMIFS('流水记账'!$G:$G,'流水记账'!$A:$A,">="&DATE(2026,3,1),'流水记账'!$A:$A,"<"&DATE(2026,4,1)) | D8: =C8-B8 | E8: =$B$2+SUM($D$6:D8)
A9: 2026年4月 | B9: =SUMIFS('流水记账'!$F:$F,'流水记账'!$A:$A,">="&DATE(2026,4,1),'流水记账'!$A:$A,"<"&DATE(2026,5,1)) | C9: =SUMIFS('流水记账'!$G:$G,'流水记账'!$A:$A,">="&DATE(2026,4,1),'流水记账'!$A:$A,"<"&DATE(2026,5,1)) | D9: =C9-B9 | E9: =$B$2+SUM($D$6:D9)
A10: 2026年5月 | B10: =SUMIFS('流水记账'!$F:$F,'流水记账'!$A:$A,">="&DATE(2026,5,1),'流水记账'!$A:$A,"<"&DATE(2026,6,1)) | C10: =SUMIFS('流水记账'!$G:$G,'流水记账'!$A:$A,">="&DATE(2026,5,1),'流水记账'!$A:$A,"<"&DATE(2026,6,1)) | D10: =C10-B10 | E10: =$B$2+SUM($D$6:D10)
A11: 2026年6月 | B11: =SUMIFS('流水记账'!$F:$F,'流水记账'!$A:$A,">="&DATE(2026,6,1),'流水记账'!$A:$A,"<"&DATE(2026,7,1)) | C11: =SUMIFS('流水记账'!$G:$G,'流水记账'!$A:$A,">="&DATE(2026,6,1),'流水记账'!$A:$A,"<"&DATE(2026,7,1)) | D11: =C11-B11 | E11: =$B$2+SUM($D$6:D11)
A12: 2026年7月 | B12: =SUMIFS('流水记账'!$F:$F,'流水记账'!$A:$A,">="&DATE(2026,7,1),'流水记账'!$A:$A,"<"&DATE(2026,8,1)) | C12: =SUMIFS('流水记账'!$G:$G,'流水记账'!$A:$A,">="&DATE(2026,7,1),'流水记账'!$A:$A,"<"&DATE(2026,8,1)) | D12: =C12-B12 | E12: =$B$2+SUM($D$6:D12)
A13: 2026年8月 | B13: =SUMIFS('流水记账'!$F:$F,'流水记账'!$A:$A,">="&DATE(2026,8,1),'流水记账'!$A:$A,"<"&DATE(2026,9,1)) | C13: =SUMIFS('流水记账'!$G:$G,'流水记账'!$A:$A,">="&DATE(2026,8,1),'流水记账'!$A:$A,"<"&DATE(2026,9,1)) | D13: =C13-B13 | E13: =$B$2+SUM($D$6:D13)
A14: 2026年9月 | B14: =SUMIFS('流水记账'!$F:$F,'流水记账'!$A:$A,">="&DATE(2026,9,1),'流水记账'!$A:$A,"<"&DATE(2026,10,1)) | C14: =SUMIFS('流水记账'!$G:$G,'流水记账'!$A:$A,">="&DATE(2026,9,1),'流水记账'!$A:$A,"<"&DATE(2026,10,1)) | D14: =C14-B14 | E14: =$B$2+SUM($D$6:D14)
A15: 2026年10月 | B15: =SUMIFS('流水记账'!$F:$F,'流水记账'!$A:$A,">="&DATE(2026,10,1),'流水记账'!$A:$A,"<"&DATE(2026,11,1)) | C15: =SUMIFS('流水记账'!$G:$G,'流水记账'!$A:$A,">="&DATE(2026,10,1),'流水记账'!$A:$A,"<"&DATE(2026,11,1)) | D15: =C15-B15 | E15: =$B$2+SUM($D$6:D15)
A16: 2026年11月 | B16: =SUMIFS('流水记账'!$F:$F,'流水记账'!$A:$A,">="&DATE(2026,11,1),'流水记账'!$A:$A,"<"&DATE(2026,12,1)) | C16: =SUMIFS('流水记账'!$G:$G,'流水记账'!$A:$A,">="&DATE(2026,11,1),'流水记账'!$A:$A,"<"&DATE(2026,12,1)) | D16: =C16-B16 | E16: =$B$2+SUM($D$6:D16)
A17: 2026年12月 | B17: =SUMIFS('流水记账'!$F:$F,'流水记账'!$A:$A,">="&DATE(2026,12,1),'流水记账'!$A:$A,"<"&DATE(2027,1,1)) | C17: =SUMIFS('流水记账'!$G:$G,'流水记账'!$A:$A,">="&DATE(2026,12,1),'流水记账'!$A:$A,"<"&DATE(2027,1,1)) | D17: =C17-B17 | E17: =$B$2+SUM($D$6:D17)
A18: 2027年1月 | B18: =SUMIFS('流水记账'!$F:$F,'流水记账'!$A:$A,">="&DATE(2027,1,1),'流水记账'!$A:$A,"<"&DATE(2027,2,1)) | C18: =SUMIFS('流水记账'!$G:$G,'流水记账'!$A:$A,">="&DATE(2027,1,1),'流水记账'!$A:$A,"<"&DATE(2027,2,1)) | D18: =C18-B18 | E18: =$B$2+SUM($D$6:D18)
A19: 2027年2月 | B19: =SUMIFS('流水记账'!$F:$F,'流水记账'!$A:$A,">="&DATE(2027,2,1),'流水记账'!$A:$A,"<"&DATE(2027,3,1)) | C19: =SUMIFS('流水记账'!$G:$G,'流水记账'!$A:$A,">="&DATE(2027,2,1),'流水记账'!$A:$A,"<"&DATE(2027,3,1)) | D19: =C19-B19 | E19: =$B$2+SUM($D$6:D19)
A20: 2027年3月 | B20: =SUMIFS('流水记账'!$F:$F,'流水记账'!$A:$A,">="&DATE(2027,3,1),'流水记账'!$A:$A,"<"&DATE(2027,4,1)) | C20: =SUMIFS('流水记账'!$G:$G,'流水记账'!$A:$A,">="&DATE(2027,3,1),'流水记账'!$A:$A,"<"&DATE(2027,4,1)) | D20: =C20-B20 | E20: =$B$2+SUM($D$6:D20)
A21: 2027年4月 | B21: =SUMIFS('流水记账'!$F:$F,'流水记账'!$A:$A,">="&DATE(2027,4,1),'流水记账'!$A:$A,"<"&DATE(2027,5,1)) | C21: =SUMIFS('流水记账'!$G:$G,'流水记账'!$A:$A,">="&DATE(2027,4,1),'流水记账'!$A:$A,"<"&DATE(2027,5,1)) | D21: =C21-B21 | E21: =$B$2+SUM($D$6:D21)
A22: 2027年5月 | B22: =SUMIFS('流水记账'!$F:$F,'流水记账'!$A:$A,">="&DATE(2027,5,1),'流水记账'!$A:$A,"<"&DATE(2027,6,1)) | C22: =SUMIFS('流水记账'!$G:$G,'流水记账'!$A:$A,">="&DATE(2027,5,1),'流水记账'!$A:$A,"<"&DATE(2027,6,1)) | D22: =C22-B22 | E22: =$B$2+SUM($D$6:D22)

Sheet 选项设置
A1: 分类 | B1: 支付方式 | C1: 事项
A2: 餐饮 | B2: 微信 | C2: 奶茶/咖啡
A3: 奶茶/咖啡 | B3: 支付宝 | C3: 交通
A4: 交通 | B4: 银行卡 | C4: 购物
A5: 购物 | B5: 现金 | C5: 娱乐
A6: 娱乐 | B6: 信用卡 | C6: 生活用品
A7: 生活用品 | B7: 其他 | C7: 旅行
A8: 旅行 | C8: 医疗
A9: 医疗 | C9: 人情/礼物
A10: 人情/礼物 | C10: 房租/固定支出
A11: 房租/固定支出 | C11: 其他
A12: 家庭支出 | C12: 早餐
A13: 其他 | C13: 中餐
C14: 晚餐
